Workbook
Name bin_lbl: Pivots!$A$66:$A$72
Name bin_lo: Pivots!$B$66:$B$72
Name c_nb: Analysis!$B$81
Name c_pt: Analysis!$B$82
Name d_age: Data_Clean!$U$2:$U$251
Name d_band: Data_Clean!$V$2:$V$251
Name d_baths: Data_Clean!$F$2:$F$251
Name d_beds: Data_Clean!$E$2:$E$251
Name d_comm: Data_Clean!$O$2:$O$251
Name d_commusd: Data_Clean!$T$2:$T$251
Name d_cond: Data_Clean!$K$2:$K$251
Name d_date: Data_Clean!$B$2:$B$251
Name d_diff: Data_Clean!$S$2:$S$251
Name d_dom: Data_Clean!$N$2:$N$251
Name d_flag: Data_Clean!$W$2:$W$251
Name d_garage: Data_Clean!$J$2:$J$251
Name d_id: Data_Clean!$A$2:$A$251
Name d_list: Data_Clean!$L$2:$L$251
Name d_lot: Data_Clean!$H$2:$H$251
Name d_month: Data_Clean!$P$2:$P$251
Name d_nbhd: Data_Clean!$C$2:$C$251
Name d_notes: Data_Clean!$X$2:$X$251
Name d_price: Data_Clean!$M$2:$M$251
Name d_psf: Data_Clean!$Q$2:$Q$251
Name d_sqft: Data_Clean!$G$2:$G$251
Name d_stl: Data_Clean!$R$2:$R$251
Name d_type: Data_Clean!$D$2:$D$251
Name d_year: Data_Clean!$I$2:$I$251
Name f_dom_hi: Analysis!$F$23
Name f_price_hi: Analysis!$F$22
Name f_psf_hi: Analysis!$F$24
Name f_psf_lo: Analysis!$E$24

Sheet Pivots
A1: PIVOT TABLES — live, formula-driven summaries of Data_Clean
A2: Every cell is a SUMIFS / COUNTIFS / AVERAGEIFS / MEDIAN(IF()) formula on the cleaned data, so all tables (and the dashboard charts built on them) refresh when Data_Clean changes. Blue = editable inputs.
A4: 1 ▸ BY NEIGHBORHOOD
A5: Neighborhood | B5: Sales | C5: % of Sales | D5: Volume ($) | E5: Avg Price | F5: Median Price | G5: Avg $/sqft | H5: Avg DOM | I5: Avg Sale-to-List | J5: Avg Commission %
A6: Cedar Park | B6: =COUNTIFS(d_nbhd,$A6) -> 39 | C6: =B6/B$12 -> 0.156 | D6: =SUMIFS(d_price,d_nbhd,$A6) -> 11140000 | E6: =IFERROR(AVERAGEIFS(d_price,d_nbhd,$A6),"") -> 285641.03 | F6: {=IFERROR(MEDIAN(IF(d_nbhd=$A6,d_price)),"")} -> 306000 | G6: =IFERROR(AVERAGEIFS(d_psf,d_nbhd,$A6),"") -> 172.14713 | H6: =IFERROR(AVERAGEIFS(d_dom,d_nbhd,$A6),"") -> 67.578947 | I6: =IFERROR(AVERAGEIFS(d_stl,d_nbhd,$A6),"") -> 0.97450341 | J6: =IFERROR(AVERAGEIFS(d_comm,d_nbhd,$A6),"") -> 2.9064865
A7: Downtown | B7: =COUNTIFS(d_nbhd,$A7) -> 36 | C7: =B7/B$12 -> 0.144 | D7: =SUMIFS(d_price,d_nbhd,$A7) -> 15479000 | E7: =IFERROR(AVERAGEIFS(d_price,d_nbhd,$A7),"") -> 429972.22 | F7: {=IFERROR(MEDIAN(IF(d_nbhd=$A7,d_price)),"")} -> 407000 | G7: =IFERROR(AVERAGEIFS(d_psf,d_nbhd,$A7),"") -> 296.95506 | H7: =IFERROR(AVERAGEIFS(d_dom,d_nbhd,$A7),"") -> 52.777778 | I7: =IFERROR(AVERAGEIFS(d_stl,d_nbhd,$A7),"") -> 0.97717766 | J7: =IFERROR(AVERAGEIFS(d_comm,d_nbhd,$A7),"") -> 2.8785714
A8: Maple Heights | B8: =COUNTIFS(d_nbhd,$A8) -> 51 | C8: =B8/B$12 -> 0.204 | D8: =SUMIFS(d_price,d_nbhd,$A8) -> 17166000 | E8: =IFERROR(AVERAGEIFS(d_price,d_nbhd,$A8),"") -> 336588.24 | F8: {=IFERROR(MEDIAN(IF(d_nbhd=$A8,d_price)),"")} -> 339000 | G8: =IFERROR(AVERAGEIFS(d_psf,d_nbhd,$A8),"") -> 193.36796 | H8: =IFERROR(AVERAGEIFS(d_dom,d_nbhd,$A8),"") -> 54.170213 | I8: =IFERROR(AVERAGEIFS(d_stl,d_nbhd,$A8),"") -> 0.97104751 | J8: =IFERROR(AVERAGEIFS(d_comm,d_nbhd,$A8),"") -> 2.9588636
A9: Oak Hill | B9: =COUNTIFS(d_nbhd,$A9) -> 58 | C9: =B9/B$12 -> 0.232 | D9: =SUMIFS(d_price,d_nbhd,$A9) -> 28572000 | E9: =IFERROR(AVERAGEIFS(d_price,d_nbhd,$A9),"") -> 492620.69 | F9: {=IFERROR(MEDIAN(IF(d_nbhd=$A9,d_price)),"")} -> 450500 | G9: =IFERROR(AVERAGEIFS(d_psf,d_nbhd,$A9),"") -> 252.82582 | H9: =IFERROR(AVERAGEIFS(d_dom,d_nbhd,$A9),"") -> 58.142857 | I9: =IFERROR(AVERAGEIFS(d_stl,d_nbhd,$A9),"") -> 0.97342954 | J9: =IFERROR(AVERAGEIFS(d_comm,d_nbhd,$A9),"") -> 2.9075439
A10: Riverside | B10: =COUNTIFS(d_nbhd,$A10) -> 62 | C10: =B10/B$12 -> 0.248 | D10: =SUMIFS(d_price,d_nbhd,$A10) -> 23755000 | E10: =IFERROR(AVERAGEIFS(d_price,d_nbhd,$A10),"") -> 383145.16 | F10: {=IFERROR(MEDIAN(IF(d_nbhd=$A10,d_price)),"")} -> 381500 | G10: =IFERROR(AVERAGEIFS(d_psf,d_nbhd,$A10),"") -> 221.25059 | H10: =IFERROR(AVERAGEIFS(d_dom,d_nbhd,$A10),"") -> 54.770492 | I10: =IFERROR(AVERAGEIFS(d_stl,d_nbhd,$A10),"") -> 0.97690998 | J10: =IFERROR(AVERAGEIFS(d_comm,d_nbhd,$A10),"") -> 2.9426316
A11: Unknown | B11: =COUNTIFS(d_nbhd,$A11) -> 4 | C11: =B11/B$12 -> 0.016 | D11: =SUMIFS(d_price,d_nbhd,$A11) -> 1488000 | E11: =IFERROR(AVERAGEIFS(d_price,d_nbhd,$A11),"") -> 372000 | F11: {=IFERROR(MEDIAN(IF(d_nbhd=$A11,d_price)),"")} -> 333000 | G11: =IFERROR(AVERAGEIFS(d_psf,d_nbhd,$A11),"") -> 207.19019 | H11: =IFERROR(AVERAGEIFS(d_dom,d_nbhd,$A11),"") -> 68.25 | I11: =IFERROR(AVERAGEIFS(d_stl,d_nbhd,$A11),"") -> 0.99839829 | J11: =IFERROR(AVERAGEIFS(d_comm,d_nbhd,$A11),"") -> 3
A12: Grand Total | B12: =SUM(B6:B11) -> 250 | C12: =SUM(C6:C11) -> 1 | D12: =SUM(D6:D11) -> 97600000 | E12: =AVERAGE(d_price) -> 390400 | F12: =MEDIAN(d_price) -> 366000 | G12: =AVERAGE(d_psf) -> 225.90432 | H12: =AVERAGE(d_dom) -> 57.371901 | I12: =AVERAGE(d_stl) -> 0.97491351 | J12: =AVERAGE(d_comm) -> 2.9224893
A14: 2 ▸ BY PROPERTY TYPE
A15: Property Type | B15: Sales | C15: % of Sales | D15: Volume ($) | E15: Avg Price | F15: Median Price | G15: Avg $/sqft | H15: Avg DOM | I15: Avg Sale-to-List | J15: Avg Commission %
A16: Condo | B16: =COUNTIFS(d_type,$A16) -> 57 | C16: =B16/B$19 -> 0.228 | D16: =SUMIFS(d_price,d_type,$A16) -> 15297000 | E16: =IFERROR(AVERAGEIFS(d_price,d_type,$A16),"") -> 268368.42 | F16: {=IFERROR(MEDIAN(IF(d_type=$A16,d_price)),"")} -> 263000 | G16: =IFERROR(AVERAGEIFS(d_psf,d_type,$A16),"") -> 235.81426 | H16: =IFERROR(AVERAGEIFS(d_dom,d_type,$A16),"") -> 59.636364 | I16: =IFERROR(AVERAGEIFS(d_stl,d_type,$A16),"") -> 0.97307063 | J16: =IFERROR(AVERAGEIFS(d_comm,d_type,$A16),"") -> 2.9592157
A17: Single Family | B17: =COUNTIFS(d_type,$A17) -> 146 | C17: =B17/B$19 -> 0.584 | D17: =SUMIFS(d_price,d_type,$A17) -> 66076000 | E17: =IFERROR(AVERAGEIFS(d_price,d_type,$A17),"") -> 452575.34 | F17: {=IFERROR(MEDIAN(IF(d_type=$A17,d_price)),"")} -> 428500 | G17: =IFERROR(AVERAGEIFS(d_psf,d_type,$A17),"") -> 225.45494 | H17: =IFERROR(AVERAGEIFS(d_dom,d_type,$A17),"") -> 57.471831 | I17: =IFERROR(AVERAGEIFS(d_stl,d_type,$A17),"") -> 0.97535231 | J17: =IFERROR(AVERAGEIFS(d_comm,d_type,$A17),"") -> 2.9161314
A18: Townhouse | B18: =COUNTIFS(d_type,$A18) -> 47 | C18: =B18/B$19 -> 0.188 | D18: =SUMIFS(d_price,d_type,$A18) -> 16227000 | E18: =IFERROR(AVERAGEIFS(d_price,d_type,$A18),"") -> 345255.32 | F18: {=IFERROR(MEDIAN(IF(d_type=$A18,d_price)),"")} -> 339000 | G18: =IFERROR(AVERAGEIFS(d_psf,d_type,$A18),"") -> 215.28185 | H18: =IFERROR(AVERAGEIFS(d_dom,d_type,$A18),"") -> 54.288889 | I18: =IFERROR(AVERAGEIFS(d_stl,d_type,$A18),"") -> 0.97578539 | J18: =IFERROR(AVERAGEIFS(d_comm,d_type,$A18),"") -> 2.9002222
A19: Grand Total | B19: =SUM(B16:B18) -> 250 | C19: =SUM(C16:C18) -> 1 | D19: =SUM(D16:D18) -> 97600000 | E19: =AVERAGE(d_price) -> 390400 | F19: =MEDIAN(d_price) -> 366000 | G19: =AVERAGE(d_psf) -> 225.90432 | H19: =AVERAGE(d_dom) -> 57.371901 | I19: =AVERAGE(d_stl) -> 0.97491351 | J19: =AVERAGE(d_comm) -> 2.9224893
A21: 3 ▸ BY CONDITION
A22: Condition | B22: Sales | C22: % of Sales | D22: Volume ($) | E22: Avg Price | F22: Median Price | G22: Avg $/sqft | H22: Avg DOM | I22: Avg Sale-to-List | J22: Avg Commission %
A23: Excellent | B23: =COUNTIFS(d_cond,$A23) -> 62 | C23: =B23/B$28 -> 0.248 | D23: =SUMIFS(d_price,d_cond,$A23) -> 28455000 | E23: =IFERROR(AVERAGEIFS(d_price,d_cond,$A23),"") -> 458951.61 | F23: {=IFERROR(MEDIAN(IF(d_cond=$A23,d_price)),"")} -> 405000 | G23: =IFERROR(AVERAGEIFS(d_psf,d_cond,$A23),"") -> 252.55274 | H23: =IFERROR(AVERAGEIFS(d_dom,d_cond,$A23),"") -> 48.901639 | I23: =IFERROR(AVERAGEIFS(d_stl,d_cond,$A23),"") -> 0.97978707 | J23: =IFERROR(AVERAGEIFS(d_comm,d_cond,$A23),"") -> 2.8951667
A24: Good | B24: =COUNTIFS(d_cond,$A24) -> 105 | C24: =B24/B$28 -> 0.42 | D24: =SUMIFS(d_price,d_cond,$A24) -> 39126000 | E24: =IFERROR(AVERAGEIFS(d_price,d_cond,$A24),"") -> 372628.57 | F24: {=IFERROR(MEDIAN(IF(d_cond=$A24,d_price)),"")} -> 364000 | G24: =IFERROR(AVERAGEIFS(d_psf,d_cond,$A24),"") -> 222.75656 | H24: =IFERROR(AVERAGEIFS(d_dom,d_cond,$A24),"") -> 52.128713 | I24: =IFERROR(AVERAGEIFS(d_stl,d_cond,$A24),"") -> 0.97112013 | J24: =IFERROR(AVERAGEIFS(d_comm,d_cond,$A24),"") -> 2.9216667
A25: Fair | B25: =COUNTIFS(d_cond,$A25) -> 60 | C25: =B25/B$28 -> 0.24 | D25: =SUMIFS(d_price,d_cond,$A25) -> 21605000 | E25: =IFERROR(AVERAGEIFS(d_price,d_cond,$A25),"") -> 360083.33 | F25: {=IFERROR(MEDIAN(IF(d_cond=$A25,d_price)),"")} -> 346000 | G25: =IFERROR(AVERAGEIFS(d_psf,d_cond,$A25),"") -> 212.47926 | H25: =IFERROR(AVERAGEIFS(d_dom,d_cond,$A25),"") -> 72.396552 | I25: =IFERROR(AVERAGEIFS(d_stl,d_cond,$A25),"") -> 0.97609542 | J25: =IFERROR(AVERAGEIFS(d_comm,d_cond,$A25),"") -> 2.9598214
A26: Poor | B26: =COUNTIFS(d_cond,$A26) -> 11 | C26: =B26/B$28 -> 0.044 | D26: =SUMIFS(d_price,d_cond,$A26) -> 3496000 | E26: =IFERROR(AVERAGEIFS(d_price,d_cond,$A26),"") -> 317818.18 | F26: {=IFERROR(MEDIAN(IF(d_cond=$A26,d_price)),"")} -> 315000 | G26: =IFERROR(AVERAGEIFS(d_psf,d_cond,$A26),"") -> 181.72841 | H26: =IFERROR(AVERAGEIFS(d_dom,d_cond,$A26),"") -> 75.3 | I26: =IFERROR(AVERAGEIFS(d_stl,d_cond,$A26),"") -> 0.98119221 | J26: =IFERROR(AVERAGEIFS(d_comm,d_cond,$A26),"") -> 2.967
A27: Unknown | B27: =COUNTIFS(d_cond,$A27) -> 12 | C27: =B27/B$28 -> 0.048 | D27: =SUMIFS(d_price,d_cond,$A27) -> 4918000 | E27: =IFERROR(AVERAGEIFS(d_price,d_cond,$A27),"") -> 409833.33 | F27: {=IFERROR(MEDIAN(IF(d_cond=$A27,d_price)),"")} -> 427500 | G27: =IFERROR(AVERAGEIFS(d_psf,d_cond,$A27),"") -> 223.38364 | H27: =IFERROR(AVERAGEIFS(d_dom,d_cond,$A27),"") -> 57 | I27: =IFERROR(AVERAGEIFS(d_stl,d_cond,$A27),"") -> 0.97126045 | J27: =IFERROR(AVERAGEIFS(d_comm,d_cond,$A27),"") -> 2.8481818
A28: Grand Total | B28: =SUM(B23:B27) -> 250 | C28: =SUM(C23:C27) -> 1 | D28: =SUM(D23:D27) -> 97600000 | E28: =AVERAGE(d_price) -> 390400 | F28: =MEDIAN(d_price) -> 366000 | G28: =AVERAGE(d_psf) -> 225.90432 | H28: =AVERAGE(d_dom) -> 57.371901 | I28: =AVERAGE(d_stl) -> 0.97491351 | J28: =AVERAGE(d_comm) -> 2.9224893
A30: 4 ▸ BY BEDROOMS (6 bedrooms = 1 sale only, treat with caution)
A31: Bedrooms | B31: Sales | C31: % of Sales | D31: Volume ($) | E31: Avg Price | F31: Median Price | G31: Avg $/sqft | H31: Avg DOM | I31: Avg Sale-to-List | J31: Avg Commission %
A32: 1 | B32: =COUNTIFS(d_beds,$A32) -> 27 | C32: =B32/B$38 -> 0.108 | D32: =SUMIFS(d_price,d_beds,$A32) -> 5999000 | E32: =IFERROR(AVERAGEIFS(d_price,d_beds,$A32),"") -> 222185.19 | F32: {=IFERROR(MEDIAN(IF(d_beds=$A32,d_price)),"")} -> 199000 | G32: =IFERROR(AVERAGEIFS(d_psf,d_beds,$A32),"") -> 252.12408 | H32: =IFERROR(AVERAGEIFS(d_dom,d_beds,$A32),"") -> 63.555556 | I32: =IFERROR(AVERAGEIFS(d_stl,d_beds,$A32),"") -> 0.98229399 | J32: =IFERROR(AVERAGEIFS(d_comm,d_beds,$A32),"") -> 2.9990909
A33: 2 | B33: =COUNTIFS(d_beds,$A33) -> 51 | C33: =B33/B$38 -> 0.204 | D33: =SUMIFS(d_price,d_beds,$A33) -> 15424000 | E33: =IFERROR(AVERAGEIFS(d_price,d_beds,$A33),"") -> 302431.37 | F33: {=IFERROR(MEDIAN(IF(d_beds=$A33,d_price)),"")} -> 301000 | G33: =IFERROR(AVERAGEIFS(d_psf,d_beds,$A33),"") -> 233.88435 | H33: =IFERROR(AVERAGEIFS(d_dom,d_beds,$A33),"") -> 57.795918 | I33: =IFERROR(AVERAGEIFS(d_stl,d_beds,$A33),"") -> 0.96993566 | J33: =IFERROR(AVERAGEIFS(d_comm,d_beds,$A33),"") -> 2.922449
A34: 3 | B34: =COUNTIFS(d_beds,$A34) -> 94 | C34: =B34/B$38 -> 0.376 | D34: =SUMIFS(d_price,d_beds,$A34) -> 35757000 | E34: =IFERROR(AVERAGEIFS(d_price,d_beds,$A34),"") -> 380393.62 | F34: {=IFERROR(MEDIAN(IF(d_beds=$A34,d_price)),"")} -> 372000 | G34: =IFERROR(AVERAGEIFS(d_psf,d_beds,$A34),"") -> 220.32431 | H34: =IFERROR(AVERAGEIFS(d_dom,d_beds,$A34),"") -> 59.133333 | I34: =IFERROR(AVERAGEIFS(d_stl,d_beds,$A34),"") -> 0.97516756 | J34: =IFERROR(AVERAGEIFS(d_comm,d_beds,$A34),"") -> 2.9226667
A35: 4 | B35: =COUNTIFS(d_beds,$A35) -> 55 | C35: =B35/B$38 -> 0.22 | D35: =SUMIFS(d_price,d_beds,$A35) -> 24672000 | E35: =IFERROR(AVERAGEIFS(d_price,d_beds,$A35),"") -> 448581.82 | F35: {=IFERROR(MEDIAN(IF(d_beds=$A35,d_price)),"")} -> 444000 | G35: =IFERROR(AVERAGEIFS(d_psf,d_beds,$A35),"") -> 212.24755 | H35: =IFERROR(AVERAGEIFS(d_dom,d_beds,$A35),"") -> 53.111111 | I35: =IFERROR(AVERAGEIFS(d_stl,d_beds,$A35),"") -> 0.97546149 | J35: =IFERROR(AVERAGEIFS(d_comm,d_beds,$A35),"") -> 2.9319608
A36: 5 | B36: =COUNTIFS(d_beds,$A36) -> 22 | C36: =B36/B$38 -> 0.088 | D36: =SUMIFS(d_price,d_beds,$A36) -> 12438000 | E36: =IFERROR(AVERAGEIFS(d_price,d_beds,$A36),"") -> 565363.64 | F36: {=IFERROR(MEDIAN(IF(d_beds=$A36,d_price)),"")} -> 541000 | G36: =IFERROR(AVERAGEIFS(d_psf,d_beds,$A36),"") -> 219.97003 | H36: =IFERROR(AVERAGEIFS(d_dom,d_beds,$A36),"") -> 51.666667 | I36: =IFERROR(AVERAGEIFS(d_stl,d_beds,$A36),"") -> 0.97564398 | J36: =IFERROR(AVERAGEIFS(d_comm,d_beds,$A36),"") -> 2.835
A37: 6 | B37: =COUNTIFS(d_beds,$A37) -> 1 | C37: =B37/B$38 -> 0.004 | D37: =SUMIFS(d_price,d_beds,$A37) -> 3310000 | E37: =IFERROR(AVERAGEIFS(d_price,d_beds,$A37),"") -> 3310000 | F37: {=IFERROR(MEDIAN(IF(d_beds=$A37,d_price)),"")} -> 3310000 | G37: =IFERROR(AVERAGEIFS(d_psf,d_beds,$A37),"") -> 517.1875 | H37: =IFERROR(AVERAGEIFS(d_dom,d_beds,$A37),"") -> 61 | I37: =IFERROR(AVERAGEIFS(d_stl,d_beds,$A37),"") -> 0.95942029 | J37: =IFERROR(AVERAGEIFS(d_comm,d_beds,$A37),"") -> 2.49
A38: Grand Total | B38: =SUM(B32:B37) -> 250 | C38: =SUM(C32:C37) -> 1 | D38: =SUM(D32:D37) -> 97600000 | E38: =AVERAGE(d_price) -> 390400 | F38: =MEDIAN(d_price) -> 366000 | G38: =AVERAGE(d_psf) -> 225.90432 | H38: =AVERAGE(d_dom) -> 57.371901 | I38: =AVERAGE(d_stl) -> 0.97491351 | J38: =AVERAGE(d_comm) -> 2.9224893
A40: 5 ▸ MONTHLY TREND (Aug-26 is a partial month — data ends 23-Aug-2026)
A41: Month | B41: Sales | C41: Volume ($) | D41: Avg Price | E41: Median Price | F41: Avg DOM | G41: Avg Sale-to-List | H41: 3-mo Rolling Avg Price | I41: Chart Label
A42: =MIN(d_month) -> 45658 | B42: =COUNTIFS(d_month,$A42) -> 17 | C42: =SUMIFS(d_price,d_month,$A42) -> 6456000 | D42: =IFERROR(AVERAGEIFS(d_price,d_month,$A42),"") -> 379764.71 | E42: {=IFERROR(MEDIAN(IF(d_month=$A42,d_price)),"")} -> 389000 | F42: =IFERROR(AVERAGEIFS(d_dom,d_month,$A42),"") -> 55.823529 | G42: =IFERROR(AVERAGEIFS(d_stl,d_month,$A42),"") -> 0.97988672 | H42: =SUM(C42:C42)/SUM(B42:B42) -> 379764.71 | I42: =TEXT(A42,"mmm-yy") -> Jan-25
A43: =EDATE(A42,1) -> 45689 | B43: =COUNTIFS(d_month,$A43) -> 12 | C43: =SUMIFS(d_price,d_month,$A43) -> 4361000 | D43: =IFERROR(AVERAGEIFS(d_price,d_month,$A43),"") -> 363416.67 | E43: {=IFERROR(MEDIAN(IF(d_month=$A43,d_price)),"")} -> 359500 | F43: =IFERROR(AVERAGEIFS(d_dom,d_month,$A43),"") -> 51.545455 | G43: =IFERROR(AVERAGEIFS(d_stl,d_month,$A43),"") -> 0.96617896 | H43: =SUM(C42:C43)/SUM(B42:B43) -> 373000 | I43: =TEXT(A43,"mmm-yy") -> Feb-25
A44: =EDATE(A43,1) -> 45717 | B44: =COUNTIFS(d_month,$A44) -> 19 | C44: =SUMIFS(d_price,d_month,$A44) -> 9849000 | D44: =IFERROR(AVERAGEIFS(d_price,d_month,$A44),"") -> 518368.42 | E44: {=IFERROR(MEDIAN(IF(d_month=$A44,d_price)),"")} -> 370000 | F44: =IFERROR(AVERAGEIFS(d_dom,d_month,$A44),"") -> 54.388889 | G44: =IFERROR(AVERAGEIFS(d_stl,d_month,$A44),"") -> 0.96938202 | H44: =SUM(C42:C44)/SUM(B42:B44) -> 430541.67 | I44: =TEXT(A44,"mmm-yy") -> Mar-25
A45: =EDATE(A44,1) -> 45748 | B45: =COUNTIFS(d_month,$A45) -> 13 | C45: =SUMIFS(d_price,d_month,$A45) -> 5756000 | D45: =IFERROR(AVERAGEIFS(d_price,d_month,$A45),"") -> 442769.23 | E45: {=IFERROR(MEDIAN(IF(d_month=$A45,d_price)),"")} -> 382000 | F45: =IFERROR(AVERAGEIFS(d_dom,d_month,$A45),"") -> 53.153846 | G45: =IFERROR(AVERAGEIFS(d_stl,d_month,$A45),"") -> 0.98632747 | H45: =SUM(C43:C45)/SUM(B43:B45) -> 453772.73 | I45: =TEXT(A45,"mmm-yy") -> Apr-25
...

Sheet Dashboard
B1: HOME SALES PERFORMANCE DASHBOARD
B2: =" "&COUNT(d_price)&" closed sales | "&TEXT(MIN(d_date),"d mmm yyyy")&" – "&TEXT(MAX(d_date),"d mmm yyyy")&" | Source: home_sales_synthetic.csv (cleaned — see Cleaning_Log)" -> 250 closed sales | 1 Jan 2025 – 23 Aug 2026 | Source: home_sales_synthetic.csv (cleaned — see Cleaning_Log)
B4: NEIGHBORHOOD ▸ | D4: All | F4: PROPERTY TYPE ▸ | H4: All | J4: ◂ dropdowns filter the KPI cards. Click any 🔍 button under a chart to open that graph's detail page.
B6: HOMES SOLD | D6: TOTAL VOLUME | F6: MEDIAN PRICE | H6: AVG $ / SQ FT | J6: AVG DAYS ON MKT | L6: SALE-TO-LIST
B7: =COUNTIFS(d_nbhd,c_nb,d_type,c_pt) -> 250 | D7: =SUMIFS(d_price,d_nbhd,c_nb,d_type,c_pt) -> 97600000 | F7: {=IFERROR(MEDIAN(IF(((Dashboard!$D$4="All")+(d_nbhd=Dashboard!$D$4)>0)*((Dashboard!$H$4="All")+(d_type=Dashboard!$H$4)>0),d_price)),"n/a")} -> 366000 | H7: =IFERROR(AVERAGEIFS(d_psf,d_nbhd,c_nb,d_type,c_pt),"n/a") -> 225.90432 | J7: =IFERROR(AVERAGEIFS(d_dom,d_nbhd,c_nb,d_type,c_pt),"n/a") -> 57.371901 | L7: =IFERROR(AVERAGEIFS(d_stl,d_nbhd,c_nb,d_type,c_pt),"n/a") -> 0.97491351
B8: ="Market: "&TEXT(COUNT(d_price),"#,##0") -> Market: 250 | D8: ="Market: "&TEXT(SUM(d_price),"$#,##0.0,,")&"M" -> Market: $97.6M | F8: ="Market: "&TEXT(MEDIAN(d_price),"$#,##0") -> Market: $3,66,000 | H8: ="Market: "&TEXT(AVERAGE(d_psf),"$#,##0") -> Market: $226 | J8: ="Market: "&TEXT(AVERAGE(d_dom),"0.0")&" days" -> Market: 57.4 days | L8: ="Market: "&TEXT(AVERAGE(d_stl),"0.0%") -> Market: 97.5%
B10: KEY INSIGHTS (auto-generated — text updates with the data)
B11: ="▲ PRICE: "&INDEX(Pivots!$A$6:$A$10,MATCH(MAX(Pivots!$E$6:$E$10),Pivots!$E$6:$E$10,0))&" is the priciest area (avg "&TEXT(MAX(Pivots!$E$6:$E$10),"$#,##0")&"); "&INDEX(Pivots!$A$6:$A$10,MATCH(MIN(Pivots!$E$6:$E$10),Pivots!$E$6:$E$10,0))&" is the most affordable ("&TEXT(MIN(Pivots!$E$6:$E$10),"$#,##0")&") — a "&TEXT(MAX(Pivots!$E$6:$E$10)/MIN(Pivots!$E$6:$E$10)-1,"0%")&" gap." -> ▲ PRICE: Oak Hill is the priciest area (avg $4,92,621); Cedar Park is the most affordable ($2,85,641) — a 72% gap.
B12: ="⏱ SPEED: "&INDEX(Pivots!$A$6:$A$10,MATCH(MIN(Pivots!$H$6:$H$10),Pivots!$H$6:$H$10,0))&" sells fastest ("&TEXT(MIN(Pivots!$H$6:$H$10),"0")&" days avg on market); "&INDEX(Pivots!$A$6:$A$10,MATCH(MAX(Pivots!$H$6:$H$10),Pivots!$H$6:$H$10,0))&" is slowest ("&TEXT(MAX(Pivots!$H$6:$H$10),"0")&" days)." -> ⏱ SPEED: Downtown sells fastest (53 days avg on market); Cedar Park is slowest (68 days).
B13: ="🏠 TYPE: Single Family homes average "&TEXT(Pivots!E17,"$#,##0")&" — "&TEXT(Pivots!E17/Pivots!E16-1,"0%")&" above condos ("&TEXT(Pivots!E16,"$#,##0")&"); townhouses sit between at "&TEXT(Pivots!E18,"$#,##0")&"." -> 🏠 TYPE: Single Family homes average $4,52,575 — 69% above condos ($2,68,368); townhouses sit between at $3,45,255.
B14: ="📐 SIZE: Living area is the strongest price driver (r = "&TEXT(Analysis!B30,"0.00")&"). Excluding outliers, each extra sq ft adds ≈ "&TEXT(Analysis!C42,"$#,##0")&" to the price (R² = "&TEXT(Analysis!C44,"0.00")&")." -> 📐 SIZE: Living area is the strongest price driver (r = 0.80). Excluding outliers, each extra sq ft adds ≈ $184 to the price (R² = 0.59).
B15: ="🤝 NEGOTIATION: Homes close at "&TEXT(Analysis!B58,"0.0%")&" of list on average — "&TEXT(Analysis!B60,"0%")&" sell above asking, "&TEXT(Analysis!B62,"0%")&" below (avg "&TEXT(-Analysis!B64,"$#,##0")&" off when they do)." -> 🤝 NEGOTIATION: Homes close at 97.5% of list on average — 19% sell above asking, 79% below (avg $14,782 off when they do).
B16: ="✨ CONDITION: Excellent homes average "&TEXT(Pivots!E23,"$#,##0")&" vs "&TEXT(Pivots!E26,"$#,##0")&" for Poor ("&TEXT(Pivots!E23/Pivots!E26-1,"0%")&" gap"&IF(AVERAGEIFS(d_sqft,d_cond,"Excellent")>1.05*AVERAGEIFS(d_sqft,d_cond,"Poor"),", partly because they are larger",", not explained by home size")&") and sell "&TEXT(Pivots!H26-Pivots!H23,"0")&" days faster." -> ✨ CONDITION: Excellent homes average $4,58,952 vs $3,17,818 for Poor (44% gap, not explained by home size) and sell 26 days faster.
B18: MARKET TREND — volume vs. price by month
B35: 🔍 Click for details & drill-down: Monthly Trend ▸
B36: NEIGHBORHOOD PERFORMANCE
B53: 🔍 Click for details & drill-down: Neighborhood Pricing ▸ | H53: 🔍 Click for details & drill-down: Speed & Negotiation ▸
B54: MARKET MIX
B71: 🔍 Click for details & drill-down: Property Type ▸ | H71: 🔍 Click for details & drill-down: Price Distribution ▸
B72: PRICE DRIVERS
B89: 🔍 Click for details & drill-down: Size vs. Price ▸ | H89: 🔍 Click for details & drill-down: Condition ▸
B90: SIZE PREMIUM & NEIGHBORHOOD × TYPE HEATMAP
H91: Average Sale Price — Neighborhood × Property Type
H92: Neighborhood | I92: Condo | J92: Single Family | K92: Townhouse | L92: All types | M92: Sales (n)
H93: =Pivots!A86 -> Cedar Park | I93: =Pivots!B86 -> 168444.44 | J93: =Pivots!C86 -> 333120 | K93: =Pivots!D86 -> 259200 | L93: =Pivots!E86 -> 285641.03 | M93: =Pivots!E106 -> 39
H94: =Pivots!A87 -> Downtown | I94: =Pivots!B87 -> 334950 | J94: =Pivots!C87 -> 576692.31 | K94: =Pivots!D87 -> 427666.67 | L94: =Pivots!E87 -> 429972.22 | M94: =Pivots!E107 -> 36
H95: =Pivots!A88 -> Maple Heights | I95: =Pivots!B88 -> 206714.29 | J95: =Pivots!C88 -> 376633.33 | K95: =Pivots!D88 -> 315714.29 | L95: =Pivots!E88 -> 336588.24 | M95: =Pivots!E108 -> 51
H96: =Pivots!A89 -> Oak Hill | I96: =Pivots!B89 -> 308090.91 | J96: =Pivots!C89 -> 572756.76 | K96: =Pivots!D89 -> 399100 | L96: =Pivots!E89 -> 492620.69 | M96: =Pivots!E109 -> 58
H97: =Pivots!A90 -> Riverside | I97: =Pivots!B90 -> 224600 | J97: =Pivots!C90 -> 434128.21 | K97: =Pivots!D90 -> 352153.85 | L97: =Pivots!E90 -> 383145.16 | M97: =Pivots!E110 -> 62
H98: =Pivots!A91 -> All areas | I98: =Pivots!B91 -> 268368.42 | J98: =Pivots!C91 -> 452575.34 | K98: =Pivots!D91 -> 345255.32 | L98: =Pivots!E91 -> 390400 | M98: =Pivots!E111 -> 250
H100: How to read: darker green = higher average price. Blank cells mean no sales in that combination (e.g. condos may not exist in every area). Bedroom chart excludes the single 6-BR sale. For full detail see the Pivots sheet.
H105: 🔍 Full heatmaps & all pivot tables ▸
B108: 🔍 Click for details & drill-down: Bedrooms ▸
B109: ="Notes: Aug-2026 is a partial month. Outliers ("&Analysis!G22&" high-price, "&Analysis!G23&" long-DOM, "&Analysis!G24&" $/sqft flags) are kept and labelled in Data_Clean › outlier_flag. Imputed values are documented in Cleaning_Log." -> Notes: Aug-2026 is a partial month. Outliers (4 high-price, 5 long-DOM, 2 $/sqft flags) are kept and labelled in Data_Clean › outlier_flag. Imputed values are documented in Cleaning_Log.

Sheet D1_Trend
B1: 1 ▸ MONTHLY TREND — DRILL-DOWN
B2: Sales volume and pricing month by month, with the rolling average that smooths short-term noise.
B3: ◂ Back to Dashboard | C3: ◂ Previous graph | E3: Next graph ▸ | G3: Graph 1 of 8 • use the buttons to move between graphs or return to the dashboard
B5: TOTAL SALES | E5: BUSIEST MONTH | H5: PEAK AVG PRICE MONTH | K5: AVG SALES / FULL MONTH
B6: =C50 -> 250 | E6: =INDEX(B30:B49,MATCH(MAX(C30:C49),C30:C49,0)) -> 46204 | H6: =INDEX(B30:B49,MATCH(MAX(E30:E49),E30:E49,0)) -> 45717 | K6: =AVERAGE(C30:C48) -> 12.894737
B7: ="Across "&COUNT(C30:C49)&" months" -> Across 20 months | E7: =MAX(C30:C49)&" homes sold" -> 21 homes sold | H7: =TEXT(MAX(E30:E49),"$#,##0")&" average" -> $5,18,368 average | K7: ="excl. partial "&TEXT(B49,"mmm-yy") -> excl. partial Aug-26
B9: THE GRAPH | I9: KEY TAKEAWAYS (auto-generated)
I10: ="Busiest month: "&TEXT(INDEX(B30:B49,MATCH(MAX(C30:C49),C30:C49,0)),"mmm-yy")&" ("&MAX(C30:C49)&" sales). Quietest full month: "&TEXT(INDEX(B30:B48,MATCH(MIN(C30:C48),C30:C48,0)),"mmm-yy")&" ("&MIN(C30:C48)&" sales)." -> Busiest month: Jul-26 (21 sales). Quietest full month: Dec-25 (7 sales).
I13: ="Average price ranged from "&TEXT(MIN(E30:E49),"$#,##0")&" ("&TEXT(INDEX(B30:B49,MATCH(MIN(E30:E49),E30:E49,0)),"mmm-yy")&") to "&TEXT(MAX(E30:E49),"$#,##0")&" ("&TEXT(INDEX(B30:B49,MATCH(MAX(E30:E49),E30:E49,0)),"mmm-yy")&")." -> Average price ranged from $3,07,444 (Apr-26) to $5,18,368 (Mar-25).
I16: ="Biggest average-vs-median gap: "&TEXT(INDEX(B30:B49,MATCH(MAX(L30:L49),L30:L49,0)),"mmm-yy")&" ("&TEXT(MAX(L30:L49),"$#,##0")&") — a few high-value sales lifted that month; the median is the fairer read." -> Biggest average-vs-median gap: Mar-25 ($1,48,368) — a few high-value sales lifted that month; the median is the fairer read.
I19: ="The 3-month rolling average moved from "&TEXT(I30,"$#,##0")&" to "&TEXT(I49,"$#,##0")&" ("&TEXT(I49/I30-1,"+0.0%;-0.0%")&") over the period." -> The 3-month rolling average moved from $3,79,765 to $3,50,314 (-7.8%) over the period.
I22: ="Volume beat the monthly average ("&TEXT(AVERAGE(C30:C49),"0.0")&") in "&COUNTIF(C30:C49,">"&AVERAGE(C30:C49))&" of "&COUNT(C30:C49)&" months." -> Volume beat the monthly average (12.5) in 9 of 20 months.
B28: DATA BEHIND THE GRAPH
B29: Month | C29: Sales | D29: Volume ($) | E29: Avg Price | F29: Median Price | G29: Avg DOM | H29: Sale-to-List | I29: 3-mo Rolling Avg | J29: Δ Avg Price MoM | K29: Δ Sales MoM | L29: Avg − Median
B30: =Pivots!A42 -> 45658 | C30: =Pivots!B42 -> 17 | D30: =Pivots!C42 -> 6456000 | E30: =Pivots!D42 -> 379764.71 | F30: =Pivots!E42 -> 389000 | G30: =Pivots!F42 -> 55.823529 | H30: =Pivots!G42 -> 0.97988672 | I30: =Pivots!H42 -> 379764.71 | J30: — | K30: — | L30: =IFERROR(E30-F30,"") -> -9235.2941
B31: =Pivots!A43 -> 45689 | C31: =Pivots!B43 -> 12 | D31: =Pivots!C43 -> 4361000 | E31: =Pivots!D43 -> 363416.67 | F31: =Pivots!E43 -> 359500 | G31: =Pivots!F43 -> 51.545455 | H31: =Pivots!G43 -> 0.96617896 | I31: =Pivots!H43 -> 373000 | J31: =IFERROR(E31/E30-1,"") -> -0.043047811 | K31: =IFERROR(C31/C30-1,"") -> -0.29411765 | L31: =IFERROR(E31-F31,"") -> 3916.6667
B32: =Pivots!A44 -> 45717 | C32: =Pivots!B44 -> 19 | D32: =Pivots!C44 -> 9849000 | E32: =Pivots!D44 -> 518368.42 | F32: =Pivots!E44 -> 370000 | G32: =Pivots!F44 -> 54.388889 | H32: =Pivots!G44 -> 0.96938202 | I32: =Pivots!H44 -> 430541.67 | J32: =IFERROR(E32/E31-1,"") -> 0.42637493 | K32: =IFERROR(C32/C31-1,"") -> 0.58333333 | L32: =IFERROR(E32-F32,"") -> 148368.42
B33: =Pivots!A45 -> 45748 | C33: =Pivots!B45 -> 13 | D33: =Pivots!C45 -> 5756000 | E33: =Pivots!D45 -> 442769.23 | F33: =Pivots!E45 -> 382000 | G33: =Pivots!F45 -> 53.153846 | H33: =Pivots!G45 -> 0.98632747 | I33: =Pivots!H45 -> 453772.73 | J33: =IFERROR(E33/E32-1,"") -> -0.14584066 | K33: =IFERROR(C33/C32-1,"") -> -0.31578947 | L33: =IFERROR(E33-F33,"") -> 60769.231
B34: =Pivots!A46 -> 45778 | C34: =Pivots!B46 -> 10 | D34: =Pivots!C46 -> 4259000 | E34: =Pivots!D46 -> 425900 | F34: =Pivots!E46 -> 380000 | G34: =Pivots!F46 -> 62.5 | H34: =Pivots!G46 -> 0.97588208 | I34: =Pivots!H46 -> 472952.38 | J34: =IFERROR(E34/E33-1,"") -> -0.038099375 | K34: =IFERROR(C34/C33-1,"") -> -0.23076923 | L34: =IFERROR(E34-F34,"") -> 45900
B35: =Pivots!A47 -> 45809 | C35: =Pivots!B47 -> 11 | D35: =Pivots!C47 -> 4532000 | E35: =Pivots!D47 -> 412000 | F35: =Pivots!E47 -> 440000 | G35: =Pivots!F47 -> 59.272727 | H35: =Pivots!G47 -> 0.97155679 | I35: =Pivots!H47 -> 427852.94 | J35: =IFERROR(E35/E34-1,"") -> -0.032636769 | K35: =IFERROR(C35/C34-1,"") -> 0.1 | L35: =IFERROR(E35-F35,"") -> -28000
B36: =Pivots!A48 -> 45839 | C36: =Pivots!B48 -> 15 | D36: =Pivots!C48 -> 5009000 | E36: =Pivots!D48 -> 333933.33 | F36: =Pivots!E48 -> 317000 | G36: =Pivots!F48 -> 55.928571 | H36: =Pivots!G48 -> 0.95814606 | I36: =Pivots!H48 -> 383333.33 | J36: =IFERROR(E36/E35-1,"") -> -0.1894822 | K36: =IFERROR(C36/C35-1,"") -> 0.36363636 | L36: =IFERROR(E36-F36,"") -> 16933.333
B37: =Pivots!A49 -> 45870 | C37: =Pivots!B49 -> 13 | D37: =Pivots!C49 -> 5202000 | E37: =Pivots!D49 -> 400153.85 | F37: =Pivots!E49 -> 373000 | G37: =Pivots!F49 -> 57.230769 | H37: =Pivots!G49 -> 0.98063578 | I37: =Pivots!H49 -> 378025.64 | J37: =IFERROR(E37/E36-1,"") -> 0.19830459 | K37: =IFERROR(C37/C36-1,"") -> -0.13333333 | L37: =IFERROR(E37-F37,"") -> 27153.846
B38: =Pivots!A50 -> 45901 | C38: =Pivots!B50 -> 12 | D38: =Pivots!C50 -> 4268000 | E38: =Pivots!D50 -> 355666.67 | F38: =Pivots!E50 -> 367500 | G38: =Pivots!F50 -> 49.583333 | H38: =Pivots!G50 -> 0.97953162 | I38: =Pivots!H50 -> 361975 | J38: =IFERROR(E38/E37-1,"") -> -0.11117519 | K38: =IFERROR(C38/C37-1,"") -> -0.076923077 | L38: =IFERROR(E38-F38,"") -> -11833.333
B39: =Pivots!A51 -> 45931 | C39: =Pivots!B51 -> 13 | D39: =Pivots!C51 -> 5222000 | E39: =Pivots!D51 -> 401692.31 | F39: =Pivots!E51 -> 422000 | G39: =Pivots!F51 -> 45.461538 | H39: =Pivots!G51 -> 0.99006871 | I39: =Pivots!H51 -> 386631.58 | J39: =IFERROR(E39/E38-1,"") -> 0.12940668 | K39: =IFERROR(C39/C38-1,"") -> 0.083333333 | L39: =IFERROR(E39-F39,"") -> -20307.692
B40: =Pivots!A52 -> 45962 | C40: =Pivots!B52 -> 11 | D40: =Pivots!C52 -> 4221000 | E40: =Pivots!D52 -> 383727.27 | F40: =Pivots!E52 -> 329000 | G40: =Pivots!F52 -> 96.5 | H40: =Pivots!G52 -> 0.96472888 | I40: =Pivots!H52 -> 380861.11 | J40: =IFERROR(E40/E39-1,"") -> -0.044723373 | K40: =IFERROR(C40/C39-1,"") -> -0.15384615 | L40: =IFERROR(E40-F40,"") -> 54727.273
B41: =Pivots!A53 -> 45992 | C41: =Pivots!B53 -> 7 | D41: =Pivots!C53 -> 2504000 | E41: =Pivots!D53 -> 357714.29 | F41: =Pivots!E53 -> 401000 | G41: =Pivots!F53 -> 63.714286 | H41: =Pivots!G53 -> 0.97114191 | I41: =Pivots!H53 -> 385387.1 | J41: =IFERROR(E41/E40-1,"") -> -0.0677903 | K41: =IFERROR(C41/C40-1,"") -> -0.36363636 | L41: =IFERROR(E41-F41,"") -> -43285.714
B42: =Pivots!A54 -> 46023 | C42: =Pivots!B54 -> 18 | D42: =Pivots!C54 -> 7468000 | E42: =Pivots!D54 -> 414888.89 | F42: =Pivots!E54 -> 383000 | G42: =Pivots!F54 -> 59.294118 | H42: =Pivots!G54 -> 0.98047141 | I42: =Pivots!H54 -> 394250 | J42: =IFERROR(E42/E41-1,"") -> 0.15983316 | K42: =IFERROR(C42/C41-1,"") -> 1.5714286 | L42: =IFERROR(E42-F42,"") -> 31888.889
... B49: =Pivots!A61 -> 46235 | C49: =Pivots!B61 -> 5 | D49: =Pivots!C61 -> 2119000 | E49: =Pivots!D61 -> 423800 | F49: =Pivots!E61 -> 355000 | G49: =Pivots!F61 -> 60.8 | H49: =Pivots!G61 -> 0.98830453 | I49: =Pivots!H61 -> 350314.29 | J49: =IFERROR(E49/E48-1,"") -> 0.28146868 | K49: =IFERROR(C49/C48-1,"") -> -0.76190476 | L49: =IFERROR(E49-F49,"") -> 68800
B50: Total / Average | C50: =SUM(C30:C49) -> 250 | D50: =SUM(D30:D49) -> 97600000 | E50: =AVERAGE(d_price) -> 390400 | F50: =MEDIAN(d_price) -> 366000 | G50: =AVERAGE(d_dom) -> 57.371901 | H50: =AVERAGE(d_stl) -> 0.97491351
B51: =" Note: "&TEXT(B49,"mmm-yy")&" is a partial month (data ends "&TEXT(MAX(d_date),"d mmm yyyy")&")." -> Note: Aug-26 is a partial month (data ends 23 Aug 2026).

Sheet D2_Neighborhood
B1: 2 ▸ NEIGHBORHOOD PRICING — DRILL-DOWN
B2: How each neighborhood prices: average vs. median, premium to market, and price per square foot.
B3: ◂ Back to Dashboard | C3: ◂ Previous graph | E3: Next graph ▸ | G3: Graph 2 of 8 • use the buttons to move between graphs or return to the dashboard
B5: HIGHEST-PRICED AREA | E5: MOST AFFORDABLE AREA | H5: PRICE SPREAD (TOP vs BOTTOM) | K5: MARKET AVG PRICE
B6: =INDEX($B$30:$B$34,MATCH(MAX($E$30:$E$34),$E$30:$E$34,0)) -> Oak Hill | E6: =INDEX($B$30:$B$34,MATCH(MIN($E$30:$E$34),$E$30:$E$34,0)) -> Cedar Park | H6: =MAX($E$30:$E$34)/MIN($E$30:$E$34)-1 -> 0.72461462 | K6: =E35 -> 390400
B7: =TEXT(MAX($E$30:$E$34),"$#,##0")&" avg price" -> $4,92,621 avg price | E7: =TEXT(MIN($E$30:$E$34),"$#,##0")&" avg price" -> $2,85,641 avg price | H7: ="premium of priciest over cheapest area" -> premium of priciest over cheapest area | K7: ="Median "&TEXT(F35,"$#,##0") -> Median $3,66,000
B9: THE GRAPH | I9: KEY TAKEAWAYS (auto-generated)
I10: ="Priciest: "&INDEX($B$30:$B$34,MATCH(MAX($E$30:$E$34),$E$30:$E$34,0))&" ("&TEXT(MAX($E$30:$E$34),"$#,##0")&"); most affordable: "&INDEX($B$30:$B$34,MATCH(MIN($E$30:$E$34),$E$30:$E$34,0))&" ("&TEXT(MIN($E$30:$E$34),"$#,##0")&") — a "&TEXT(MAX($E$30:$E$34)/MIN($E$30:$E$34)-1,"0%")&" spread." -> Priciest: Oak Hill ($4,92,621); most affordable: Cedar Park ($2,85,641) — a 72% spread.
I13: ="Largest share of sales: "&INDEX($B$30:$B$34,MATCH(MAX($C$30:$C$34),$C$30:$C$34,0))&" ("&TEXT(MAX($D$30:$D$34),"0.0%")&" of all sales)." -> Largest share of sales: Riverside (24.8% of all sales).
I16: ="Widest average-vs-median gap: "&INDEX($B$30:$B$34,MATCH(MAX($G$30:$G$34),$G$30:$G$34,0))&" ("&TEXT(MAX($G$30:$G$34),"$#,##0")&") — a few expensive sales lift its average." -> Widest average-vs-median gap: Oak Hill ($42,121) — a few expensive sales lift its average.
I19: ="Best value per sq ft: "&INDEX($B$30:$B$34,MATCH(MIN($I$30:$I$34),$I$30:$I$34,0))&" ("&TEXT(MIN($I$30:$I$34),"$#,##0")&") vs "&INDEX($B$30:$B$34,MATCH(MAX($I$30:$I$34),$I$30:$I$34,0))&" ("&TEXT(MAX($I$30:$I$34),"$#,##0")&")." -> Best value per sq ft: Cedar Park ($172) vs Downtown ($297).
I22: =COUNTIF($H$30:$H$34,">0")&" of "&COUNT($H$30:$H$34)&" neighborhoods price above the market average." -> 2 of 5 neighborhoods price above the market average.
B28: DATA BEHIND THE GRAPH
B29: Neighborhood | C29: Sales | D29: % of Sales | E29: Avg Price | F29: Median Price | G29: Avg − Median | H29: Avg vs Market | I29: Avg $/sqft | J29: Avg Sq Ft | K29: Price Rank
B30: Cedar Park | C30: =COUNTIFS(d_nbhd,$B30) -> 39 | D30: =C30/C$35 -> 0.156 | E30: =IFERROR(AVERAGEIFS(d_price,d_nbhd,$B30),"") -> 285641.03 | F30: {=IFERROR(MEDIAN(IF(d_nbhd=$B30,d_price)),"")} -> 306000 | G30: =IFERROR(E30-F30,"") -> -20358.974 | H30: =IFERROR(E30/E$35-1,"") -> -0.26833754 | I30: =IFERROR(AVERAGEIFS(d_psf,d_nbhd,$B30),"") -> 172.14713 | J30: =IFERROR(AVERAGEIFS(d_sqft,d_nbhd,$B30),"") -> 1668.7179 | K30: =RANK(E30,E$30:E$34) -> 5
B31: Downtown | C31: =COUNTIFS(d_nbhd,$B31) -> 36 | D31: =C31/C$35 -> 0.144 | E31: =IFERROR(AVERAGEIFS(d_price,d_nbhd,$B31),"") -> 429972.22 | F31: {=IFERROR(MEDIAN(IF(d_nbhd=$B31,d_price)),"")} -> 407000 | G31: =IFERROR(E31-F31,"") -> 22972.222 | H31: =IFERROR(E31/E$35-1,"") -> 0.10136327 | I31: =IFERROR(AVERAGEIFS(d_psf,d_nbhd,$B31),"") -> 296.95506 | J31: =IFERROR(AVERAGEIFS(d_sqft,d_nbhd,$B31),"") -> 1458.8889 | K31: =RANK(E31,E$30:E$34) -> 2
B32: Maple Heights | C32: =COUNTIFS(d_nbhd,$B32) -> 51 | D32: =C32/C$35 -> 0.204 | E32: =IFERROR(AVERAGEIFS(d_price,d_nbhd,$B32),"") -> 336588.24 | F32: {=IFERROR(MEDIAN(IF(d_nbhd=$B32,d_price)),"")} -> 339000 | G32: =IFERROR(E32-F32,"") -> -2411.7647 | H32: =IFERROR(E32/E$35-1,"") -> -0.13783751 | I32: =IFERROR(AVERAGEIFS(d_psf,d_nbhd,$B32),"") -> 193.36796 | J32: =IFERROR(AVERAGEIFS(d_sqft,d_nbhd,$B32),"") -> 1758.2353 | K32: =RANK(E32,E$30:E$34) -> 4
B33: Oak Hill | C33: =COUNTIFS(d_nbhd,$B33) -> 58 | D33: =C33/C$35 -> 0.232 | E33: =IFERROR(AVERAGEIFS(d_price,d_nbhd,$B33),"") -> 492620.69 | F33: {=IFERROR(MEDIAN(IF(d_nbhd=$B33,d_price)),"")} -> 450500 | G33: =IFERROR(E33-F33,"") -> 42120.69 | H33: =IFERROR(E33/E$35-1,"") -> 0.26183578 | I33: =IFERROR(AVERAGEIFS(d_psf,d_nbhd,$B33),"") -> 252.82582 | J33: =IFERROR(AVERAGEIFS(d_sqft,d_nbhd,$B33),"") -> 1877.931 | K33: =RANK(E33,E$30:E$34) -> 1
B34: Riverside | C34: =COUNTIFS(d_nbhd,$B34) -> 62 | D34: =C34/C$35 -> 0.248 | E34: =IFERROR(AVERAGEIFS(d_price,d_nbhd,$B34),"") -> 383145.16 | F34: {=IFERROR(MEDIAN(IF(d_nbhd=$B34,d_price)),"")} -> 381500 | G34: =IFERROR(E34-F34,"") -> 1645.1613 | H34: =IFERROR(E34/E$35-1,"") -> -0.018583091 | I34: =IFERROR(AVERAGEIFS(d_psf,d_nbhd,$B34),"") -> 221.25059 | J34: =IFERROR(AVERAGEIFS(d_sqft,d_nbhd,$B34),"") -> 1745.1613 | K34: =RANK(E34,E$30:E$34) -> 3
B35: Market (all sales) | C35: =COUNT(d_price) -> 250 | D35: =C35/C$35 -> 1 | E35: =AVERAGE(d_price) -> 390400 | F35: =MEDIAN(d_price) -> 366000 | G35: =IFERROR(E35-F35,"") -> 24400 | H35: — | I35: =AVERAGE(d_psf) -> 225.90432 | J35: =AVERAGE(d_sqft) -> 1727.04 | K35: —
B36: ="Note: "&COUNTIF(d_nbhd,"Unknown")&" sales have an unknown neighborhood — they count in the Market row only." -> Note: 4 sales have an unknown neighborhood — they count in the Market row only.
B38: DRILL-DOWN ▸ pick a neighborhood to see its full profile
B39: Choose neighborhood ▸ | C39: Oak Hill
B41: Metric | C41: Selected | D41: Market | E41: Difference | G41: Type mix | H41: Sales | I41: Avg price | J41: Avg $/sqft
B42: Sales (n) | C42: =COUNTIFS(d_nbhd,$C$39) -> 58 | D42: =COUNT(d_price) -> 250 | E42: =IFERROR(C42-D42,"") -> -192 | G42: Condo | H42: =COUNTIFS(d_nbhd,$C$39,d_type,G42) -> 11 | I42: =IFERROR(AVERAGEIFS(d_price,d_nbhd,$C$39,d_type,G42),"—") -> 308090.91 | J42: =IFERROR(AVERAGEIFS(d_psf,d_nbhd,$C$39,d_type,G42),"—") -> 236.25446
B43: Avg price | C43: =IFERROR(AVERAGEIFS(d_price,d_nbhd,$C$39),"") -> 492620.69 | D43: =AVERAGE(d_price) -> 390400 | E43: =IFERROR(C43-D43,"") -> 102220.69 | G43: Single Family | H43: =COUNTIFS(d_nbhd,$C$39,d_type,G43) -> 37 | I43: =IFERROR(AVERAGEIFS(d_price,d_nbhd,$C$39,d_type,G43),"—") -> 572756.76 | J43: =IFERROR(AVERAGEIFS(d_psf,d_nbhd,$C$39,d_type,G43),"—") -> 258.38389
B44: Median price | C44: {=IFERROR(MEDIAN(IF(d_nbhd=$C$39,d_price)),"")} -> 450500 | D44: =MEDIAN(d_price) -> 366000 | E44: =IFERROR(C44-D44,"") -> 84500 | G44: Townhouse | H44: =COUNTIFS(d_nbhd,$C$39,d_type,G44) -> 10 | I44: =IFERROR(AVERAGEIFS(d_price,d_nbhd,$C$39,d_type,G44),"—") -> 399100 | J44: =IFERROR(AVERAGEIFS(d_psf,d_nbhd,$C$39,d_type,G44),"—") -> 250.48942
B45: Avg $/sqft | C45: =IFERROR(AVERAGEIFS(d_psf,d_nbhd,$C$39),"") -> 252.82582 | D45: =AVERAGE(d_psf) -> 225.90432 | E45: =IFERROR(C45-D45,"") -> 26.921492
B46: Avg sq ft | C46: =IFERROR(AVERAGEIFS(d_sqft,d_nbhd,$C$39),"") -> 1877.931 | D46: =AVERAGE(d_sqft) -> 1727.04 | E46: =IFERROR(C46-D46,"") -> 150.89103 | G46: ="Top type: "&INDEX(G42:G44,MATCH(MAX(H42:H44),H42:H44,0))&" ("&TEXT(MAX(H42:H44)/C42,"0%")&" of this area's sales)" -> Top type: Single Family (64% of this area's sales)
B47: Avg bedrooms | C47: =IFERROR(AVERAGEIFS(d_beds,d_nbhd,$C$39),"") -> 3.1896552 | D47: =AVERAGE(d_beds) -> 2.988 | E47: =IFERROR(C47-D47,"") -> 0.20165517
B48: Avg days on market | C48: =IFERROR(AVERAGEIFS(d_dom,d_nbhd,$C$39),"") -> 58.142857 | D48: =AVERAGE(d_dom) -> 57.371901 | E48: =IFERROR(C48-D48,"") -> 0.77095632
B49: Sale-to-list | C49: =IFERROR(AVERAGEIFS(d_stl,d_nbhd,$C$39),"") -> 0.97342954 | D49: =AVERAGE(d_stl) -> 0.97491351 | E49: =IFERROR(C49-D49,"") -> -0.0014839709
B50: % sold above list | C50: =IFERROR(COUNTIFS(d_nbhd,$C$39,d_stl,">1")/COUNTIFS(d_nbhd,$C$39),"") -> 0.13793103 | D50: =COUNTIF(d_stl,">1")/COUNT(d_stl) -> 0.192 | E50: =IFERROR(C50-D50,"") -> -0.054068966

Sheet D3_Speed_Negotiation
B1: 3 ▸ SPEED & NEGOTIATION — DRILL-DOWN
B2: How fast each neighborhood sells and how much room buyers have to negotiate.
B3: ◂ Back to Dashboard | C3: ◂ Previous graph | E3: Next graph ▸ | G3: Graph 3 of 8 • use the buttons to move between graphs or return to the dashboard
B5: FASTEST-SELLING AREA | E5: SLOWEST-SELLING AREA | H5: MARKET SALE-TO-LIST | K5: % SOLD ABOVE ASKING
B6: =INDEX($B$30:$B$34,MATCH(MIN($D$30:$D$34),$D$30:$D$34,0)) -> Downtown | E6: =INDEX($B$30:$B$34,MATCH(MAX($D$30:$D$34),$D$30:$D$34,0)) -> Cedar Park | H6: =F35 -> 0.97491351 | K6: =G35 -> 0.192
B7: =TEXT(MIN($D$30:$D$34),"0.0")&" days on market" -> 52.8 days on market | E7: =TEXT(MAX($D$30:$D$34),"0.0")&" days on market" -> 67.6 days on market | H7: ="Median DOM "&TEXT(E35,"0")&" days" -> Median DOM 53 days | K7: =TEXT(H35,"0%")&" sold below" -> 79% sold below
B9: THE GRAPH | I9: KEY TAKEAWAYS (auto-generated)
I10: ="Fastest: "&INDEX($B$30:$B$34,MATCH(MIN($D$30:$D$34),$D$30:$D$34,0))&" ("&TEXT(MIN($D$30:$D$34),"0.0")&" days); slowest: "&INDEX($B$30:$B$34,MATCH(MAX($D$30:$D$34),$D$30:$D$34,0))&" ("&TEXT(MAX($D$30:$D$34),"0.0")&" days) — a "&TEXT(MAX($D$30:$D$34)-MIN($D$30:$D$34),"0")&"-day difference." -> Fastest: Downtown (52.8 days); slowest: Cedar Park (67.6 days) — a 15-day difference.
I13: ="Sale-to-list runs from "&TEXT(MIN($F$30:$F$34),"0.0%")&" ("&INDEX($B$30:$B$34,MATCH(MIN($F$30:$F$34),$F$30:$F$34,0))&") to "&TEXT(MAX($F$30:$F$34),"0.0%")&" ("&INDEX($B$30:$B$34,MATCH(MAX($F$30:$F$34),$F$30:$F$34,0))&") — a "&TEXT((MAX($F$30:$F$34)-MIN($F$30:$F$34))*100,"0.0")&"-point spread." -> Sale-to-list runs from 97.1% (Maple Heights) to 97.7% (Downtown) — a 0.6-point spread.
I16: ="Most above-asking sales: "&INDEX($B$30:$B$34,MATCH(MAX($G$30:$G$34),$G$30:$G$34,0))&" ("&TEXT(MAX($G$30:$G$34),"0%")&" of its sales closed over list)." -> Most above-asking sales: Riverside (26% of its sales closed over list).
I19: ="Market median time on market is "&TEXT(E35,"0")&" days vs a mean of "&TEXT(D35,"0.0")&IF(D35>E35," — a few very slow listings pull the mean up.",".") -> Market median time on market is 53 days vs a mean of 57.4 — a few very slow listings pull the mean up.
I22: ="When homes sell below list, the average discount is "&TEXT(-Analysis!B64,"$#,##0")&"." -> When homes sell below list, the average discount is $14,782.
B28: DATA BEHIND THE GRAPH
B29: Neighborhood | C29: Sales | D29: Avg DOM (days) | E29: Median DOM | F29: Sale-to-List | G29: % Sold Above List | H29: % Sold Below List | I29: Avg $ vs List | J29: Avg Comm. %
B30: Cedar Park | C30: =COUNTIFS(d_nbhd,$B30) -> 39 | D30: =IFERROR(AVERAGEIFS(d_dom,d_nbhd,$B30),"") -> 67.578947 | E30: {=IFERROR(MEDIAN(IF((d_nbhd=$B30)*(d_dom<>""),d_dom)),"")} -> 59.5 | F30: =IFERROR(AVERAGEIFS(d_stl,d_nbhd,$B30),"") -> 0.97450341 | G30: =IFERROR(COUNTIFS(d_nbhd,$B30,d_stl,">1")/COUNTIFS(d_nbhd,$B30),"") -> 0.15384615 | H30: =IFERROR(COUNTIFS(d_nbhd,$B30,d_stl,"<1")/COUNTIFS(d_nbhd,$B30),"") -> 0.79487179 | I30: =IFERROR(AVERAGEIFS(d_diff,d_nbhd,$B30),"") -> -7512.8205 | J30: =IFERROR(AVERAGEIFS(d_comm,d_nbhd,$B30),"") -> 2.9064865
B31: Downtown | C31: =COUNTIFS(d_nbhd,$B31) -> 36 | D31: =IFERROR(AVERAGEIFS(d_dom,d_nbhd,$B31),"") -> 52.777778 | E31: {=IFERROR(MEDIAN(IF((d_nbhd=$B31)*(d_dom<>""),d_dom)),"")} -> 49 | F31: =IFERROR(AVERAGEIFS(d_stl,d_nbhd,$B31),"") -> 0.97717766 | G31: =IFERROR(COUNTIFS(d_nbhd,$B31,d_stl,">1")/COUNTIFS(d_nbhd,$B31),"") -> 0.19444444 | H31: =IFERROR(COUNTIFS(d_nbhd,$B31,d_stl,"<1")/COUNTIFS(d_nbhd,$B31),"") -> 0.80555556 | I31: =IFERROR(AVERAGEIFS(d_diff,d_nbhd,$B31),"") -> -10805.556 | J31: =IFERROR(AVERAGEIFS(d_comm,d_nbhd,$B31),"") -> 2.8785714
B32: Maple Heights | C32: =COUNTIFS(d_nbhd,$B32) -> 51 | D32: =IFERROR(AVERAGEIFS(d_dom,d_nbhd,$B32),"") -> 54.170213 | E32: {=IFERROR(MEDIAN(IF((d_nbhd=$B32)*(d_dom<>""),d_dom)),"")} -> 52 | F32: =IFERROR(AVERAGEIFS(d_stl,d_nbhd,$B32),"") -> 0.97104751 | G32: =IFERROR(COUNTIFS(d_nbhd,$B32,d_stl,">1")/COUNTIFS(d_nbhd,$B32),"") -> 0.19607843 | H32: =IFERROR(COUNTIFS(d_nbhd,$B32,d_stl,"<1")/COUNTIFS(d_nbhd,$B32),"") -> 0.78431373 | I32: =IFERROR(AVERAGEIFS(d_diff,d_nbhd,$B32),"") -> -9921.5686 | J32: =IFERROR(AVERAGEIFS(d_comm,d_nbhd,$B32),"") -> 2.9588636
B33: Oak Hill | C33: =COUNTIFS(d_nbhd,$B33) -> 58 | D33: =IFERROR(AVERAGEIFS(d_dom,d_nbhd,$B33),"") -> 58.142857 | E33: {=IFERROR(MEDIAN(IF((d_nbhd=$B33)*(d_dom<>""),d_dom)),"")} -> 57 | F33: =IFERROR(AVERAGEIFS(d_stl,d_nbhd,$B33),"") -> 0.97342954 | G33: =IFERROR(COUNTIFS(d_nbhd,$B33,d_stl,">1")/COUNTIFS(d_nbhd,$B33),"") -> 0.13793103 | H33: =IFERROR(COUNTIFS(d_nbhd,$B33,d_stl,"<1")/COUNTIFS(d_nbhd,$B33),"") -> 0.84482759 | I33: =IFERROR(AVERAGEIFS(d_diff,d_nbhd,$B33),"") -> -14172.414 | J33: =IFERROR(AVERAGEIFS(d_comm,d_nbhd,$B33),"") -> 2.9075439
B34: Riverside | C34: =COUNTIFS(d_nbhd,$B34) -> 62 | D34: =IFERROR(AVERAGEIFS(d_dom,d_nbhd,$B34),"") -> 54.770492 | E34: {=IFERROR(MEDIAN(IF((d_nbhd=$B34)*(d_dom<>""),d_dom)),"")} -> 48 | F34: =IFERROR(AVERAGEIFS(d_stl,d_nbhd,$B34),"") -> 0.97690998 | G34: =IFERROR(COUNTIFS(d_nbhd,$B34,d_stl,">1")/COUNTIFS(d_nbhd,$B34),"") -> 0.25806452 | H34: =IFERROR(COUNTIFS(d_nbhd,$B34,d_stl,"<1")/COUNTIFS(d_nbhd,$B34),"") -> 0.74193548 | I34: =IFERROR(AVERAGEIFS(d_diff,d_nbhd,$B34),"") -> -8451.6129 | J34: =IFERROR(AVERAGEIFS(d_comm,d_nbhd,$B34),"") -> 2.9426316
B35: Market (all sales) | C35: =COUNT(d_price) -> 250 | D35: =AVERAGE(d_dom) -> 57.371901 | E35: =MEDIAN(d_dom) -> 53 | F35: =AVERAGE(d_stl) -> 0.97491351 | G35: =COUNTIF(d_stl,">1")/COUNT(d_stl) -> 0.192 | H35: =COUNTIF(d_stl,"<1")/COUNT(d_stl) -> 0.788 | I35: =AVERAGE(d_diff) -> -10156 | J35: =AVERAGE(d_comm) -> 2.9224893
B37: Does waiting cost / save money? | C37: Sales | D37: Avg Sale-to-List | E37: Avg Price
B38: =Analysis!A67 -> Fast (≤ 40 days) | C38: =Analysis!D67 -> 56 | D38: =Analysis!E67 -> 0.97755475 | E38: =Analysis!F67 -> 385857.14
B39: =Analysis!A68 -> Normal (41-60) | C39: =Analysis!D68 -> 97 | D39: =Analysis!E68 -> 0.97814724 | E39: =Analysis!F68 -> 386391.75
B40: =Analysis!A69 -> Slow (61-90) | C40: =Analysis!D69 -> 69 | D40: =Analysis!E69 -> 0.96946971 | E40: =Analysis!F69 -> 408434.78
B41: =Analysis!A70 -> Very slow (> 90) | C41: =Analysis!D70 -> 20 | D41: =Analysis!E70 -> 0.97271204 | E41: =Analysis!F70 -> 381800

Sheet D4_Property_Type
B1: 4 ▸ PROPERTY TYPE — DRILL-DOWN
B2: Condos, single-family homes and townhouses compared on price, size, speed and negotiation.
B3: ◂ Back to Dashboard | C3: ◂ Previous graph | E3: Next graph ▸ | G3: Graph 4 of 8 • use the buttons to move between graphs or return to the dashboard
B5: LARGEST SEGMENT | E5: SINGLE FAMILY vs CONDO | H5: HIGHEST $/SQ FT | K5: MARKET MEDIAN PRICE
B6: =INDEX($B$30:$B$32,MATCH(MAX($C$30:$C$32),$C$30:$C$32,0)) -> Single Family | E6: =E31/E30-1 -> 0.68639567 | H6: =INDEX($B$30:$B$32,MATCH(MAX($G$30:$G$32),$G$30:$G$32,0)) -> Condo | K6: =F33 -> 366000
B7: =TEXT(MAX($D$30:$D$32),"0%")&" of all sales" -> 58% of all sales | E7: ="average price premium" -> average price premium | H7: =TEXT(MAX($G$30:$G$32),"$#,##0")&" per sq ft" -> $236 per sq ft | K7: ="Avg "&TEXT(E33,"$#,##0") -> Avg $3,90,400
B9: THE GRAPH | I9: KEY TAKEAWAYS (auto-generated)
I10: ="Largest segment: "&INDEX($B$30:$B$32,MATCH(MAX($C$30:$C$32),$C$30:$C$32,0))&" — "&TEXT(MAX($D$30:$D$32),"0%")&" of sales ("&MAX($C$30:$C$32)&" homes)." -> Largest segment: Single Family — 58% of sales (146 homes).
I13: ="Single Family averages "&TEXT(E31,"$#,##0")&", "&TEXT(E31/E30-1,"0%")&" above condos ("&TEXT(E30,"$#,##0")&"); townhouses sit at "&TEXT(E32,"$#,##0")&"." -> Single Family averages $4,52,575, 69% above condos ($2,68,368); townhouses sit at $3,45,255.
I16: ="Part of that gap is space: Single Family homes average "&TEXT(H31,"#,##0")&" sq ft vs "&TEXT(H30,"#,##0")&" for condos. Per sq ft, "&INDEX($B$30:$B$32,MATCH(MAX($G$30:$G$32),$G$30:$G$32,0))&" leads ("&TEXT(MAX($G$30:$G$32),"$#,##0")&")." -> Part of that gap is space: Single Family homes average 1,981 sq ft vs 1,158 for condos. Per sq ft, Condo leads ($236).
I19: ="Fastest to sell: "&INDEX($B$30:$B$32,MATCH(MIN($J$30:$J$32),$J$30:$J$32,0))&" ("&TEXT(MIN($J$30:$J$32),"0.0")&" days on market)." -> Fastest to sell: Townhouse (54.3 days on market).
I22: ="Highest sale-to-list: "&INDEX($B$30:$B$32,MATCH(MAX($K$30:$K$32),$K$30:$K$32,0))&" ("&TEXT(MAX($K$30:$K$32),"0.0%")&"); lowest: "&INDEX($B$30:$B$32,MATCH(MIN($K$30:$K$32),$K$30:$K$32,0))&" ("&TEXT(MIN($K$30:$K$32),"0.0%")&")." -> Highest sale-to-list: Townhouse (97.6%); lowest: Condo (97.3%).
B28: DATA BEHIND THE GRAPH
B29: Property Type | C29: Sales | D29: % of Sales | E29: Avg Price | F29: Median Price | G29: Avg $/sqft | H29: Avg Sq Ft | I29: Avg Beds | J29: Avg DOM (days) | K29: Sale-to-List | L29: Price Rank
B30: Condo | C30: =COUNTIFS(d_type,$B30) -> 57 | D30: =C30/C$33 -> 0.228 | E30: =IFERROR(AVERAGEIFS(d_price,d_type,$B30),"") -> 268368.42 | F30: {=IFERROR(MEDIAN(IF(d_type=$B30,d_price)),"")} -> 263000 | G30: =IFERROR(AVERAGEIFS(d_psf,d_type,$B30),"") -> 235.81426 | H30: =IFERROR(AVERAGEIFS(d_sqft,d_type,$B30),"") -> 1157.5439 | I30: =IFERROR(AVERAGEIFS(d_beds,d_type,$B30),"") -> 1.6315789 | J30: =IFERROR(AVERAGEIFS(d_dom,d_type,$B30),"") -> 59.636364 | K30: =IFERROR(AVERAGEIFS(d_stl,d_type,$B30),"") -> 0.97307063 | L30: =RANK(E30,E$30:E$32) -> 3
B31: Single Family | C31: =COUNTIFS(d_type,$B31) -> 146 | D31: =C31/C$33 -> 0.584 | E31: =IFERROR(AVERAGEIFS(d_price,d_type,$B31),"") -> 452575.34 | F31: {=IFERROR(MEDIAN(IF(d_type=$B31,d_price)),"")} -> 428500 | G31: =IFERROR(AVERAGEIFS(d_psf,d_type,$B31),"") -> 225.45494 | H31: =IFERROR(AVERAGEIFS(d_sqft,d_type,$B31),"") -> 1980.8219 | I31: =IFERROR(AVERAGEIFS(d_beds,d_type,$B31),"") -> 3.5821918 | J31: =IFERROR(AVERAGEIFS(d_dom,d_type,$B31),"") -> 57.471831 | K31: =IFERROR(AVERAGEIFS(d_stl,d_type,$B31),"") -> 0.97535231 | L31: =RANK(E31,E$30:E$32) -> 1
B32: Townhouse | C32: =COUNTIFS(d_type,$B32) -> 47 | D32: =C32/C$33 -> 0.188 | E32: =IFERROR(AVERAGEIFS(d_price,d_type,$B32),"") -> 345255.32 | F32: {=IFERROR(MEDIAN(IF(d_type=$B32,d_price)),"")} -> 339000 | G32: =IFERROR(AVERAGEIFS(d_psf,d_type,$B32),"") -> 215.28185 | H32: =IFERROR(AVERAGEIFS(d_sqft,d_type,$B32),"") -> 1629.3617 | I32: =IFERROR(AVERAGEIFS(d_beds,d_type,$B32),"") -> 2.787234 | J32: =IFERROR(AVERAGEIFS(d_dom,d_type,$B32),"") -> 54.288889 | K32: =IFERROR(AVERAGEIFS(d_stl,d_type,$B32),"") -> 0.97578539 | L32: =RANK(E32,E$30:E$32) -> 2
B33: Market (all sales) | C33: =COUNT(d_price) -> 250 | D33: =C33/C$33 -> 1 | E33: =AVERAGE(d_price) -> 390400 | F33: =MEDIAN(d_price) -> 366000 | G33: =AVERAGE(d_psf) -> 225.90432 | H33: =AVERAGE(d_sqft) -> 1727.04 | I33: =AVERAGE(d_beds) -> 2.988 | J33: =AVERAGE(d_dom) -> 57.371901 | K33: =AVERAGE(d_stl) -> 0.97491351 | L33: —
B36: DRILL-DOWN ▸ pick a property type to see where it sells
B37: Choose property type ▸ | C37: Single Family
B39: Neighborhood | C39: Sales | D39: % of this type | E39: Avg Price | F39: Avg $/sqft | G39: Avg DOM | H39: Sale-to-List
B40: Cedar Park | C40: =COUNTIFS(d_type,$C$37,d_nbhd,$B40) -> 25 | D40: =C40/COUNTIFS(d_type,$C$37) -> 0.17123288 | E40: =IFERROR(AVERAGEIFS(d_price,d_type,$C$37,d_nbhd,$B40),"—") -> 333120 | F40: =IFERROR(AVERAGEIFS(d_psf,d_type,$C$37,d_nbhd,$B40),"—") -> 177.64611 | G40: =IFERROR(AVERAGEIFS(d_dom,d_type,$C$37,d_nbhd,$B40),"—") -> 60.24 | H40: =IFERROR(AVERAGEIFS(d_stl,d_type,$C$37,d_nbhd,$B40),"—") -> 0.97720659
B41: Downtown | C41: =COUNTIFS(d_type,$C$37,d_nbhd,$B41) -> 13 | D41: =C41/COUNTIFS(d_type,$C$37) -> 0.089041096 | E41: =IFERROR(AVERAGEIFS(d_price,d_type,$C$37,d_nbhd,$B41),"—") -> 576692.31 | F41: =IFERROR(AVERAGEIFS(d_psf,d_type,$C$37,d_nbhd,$B41),"—") -> 305.97859 | G41: =IFERROR(AVERAGEIFS(d_dom,d_type,$C$37,d_nbhd,$B41),"—") -> 52.846154 | H41: =IFERROR(AVERAGEIFS(d_stl,d_type,$C$37,d_nbhd,$B41),"—") -> 0.97881131
B42: Maple Heights | C42: =COUNTIFS(d_type,$C$37,d_nbhd,$B42) -> 30 | D42: =C42/COUNTIFS(d_type,$C$37) -> 0.20547945 | E42: =IFERROR(AVERAGEIFS(d_price,d_type,$C$37,d_nbhd,$B42),"—") -> 376633.33 | F42: =IFERROR(AVERAGEIFS(d_psf,d_type,$C$37,d_nbhd,$B42),"—") -> 197.9114 | G42: =IFERROR(AVERAGEIFS(d_dom,d_type,$C$37,d_nbhd,$B42),"—") -> 53.035714 | H42: =IFERROR(AVERAGEIFS(d_stl,d_type,$C$37,d_nbhd,$B42),"—") -> 0.97223216
B43: Oak Hill | C43: =COUNTIFS(d_type,$C$37,d_nbhd,$B43) -> 37 | D43: =C43/COUNTIFS(d_type,$C$37) -> 0.25342466 | E43: =IFERROR(AVERAGEIFS(d_price,d_type,$C$37,d_nbhd,$B43),"—") -> 572756.76 | F43: =IFERROR(AVERAGEIFS(d_psf,d_type,$C$37,d_nbhd,$B43),"—") -> 258.38389 | G43: =IFERROR(AVERAGEIFS(d_dom,d_type,$C$37,d_nbhd,$B43),"—") -> 58.571429 | H43: =IFERROR(AVERAGEIFS(d_stl,d_type,$C$37,d_nbhd,$B43),"—") -> 0.97163473
B44: Riverside | C44: =COUNTIFS(d_type,$C$37,d_nbhd,$B44) -> 39 | D44: =C44/COUNTIFS(d_type,$C$37) -> 0.26712329 | E44: =IFERROR(AVERAGEIFS(d_price,d_type,$C$37,d_nbhd,$B44),"—") -> 434128.21 | F44: =IFERROR(AVERAGEIFS(d_psf,d_type,$C$37,d_nbhd,$B44),"—") -> 221.06576 | G44: =IFERROR(AVERAGEIFS(d_dom,d_type,$C$37,d_nbhd,$B44),"—") -> 58.435897 | H44: =IFERROR(AVERAGEIFS(d_stl,d_type,$C$37,d_nbhd,$B44),"—") -> 0.97775109

Sheet D5_Price_Distribution
B1: 5 ▸ PRICE DISTRIBUTION — DRILL-DOWN
B2: How sale prices are distributed across bands, with percentiles and the skew created by luxury sales.
B3: ◂ Back to Dashboard | C3: ◂ Previous graph | E3: Next graph ▸ | G3: Graph 5 of 8 • use the buttons to move between graphs or return to the dashboard
B5: MOST COMMON PRICE BAND | E5: MEDIAN PRICE | H5: SHARE UNDER $300K | K5: SHARE $600K AND UP
B6: =INDEX(B30:B36,MATCH(MAX(C30:C36),C30:C36,0)) -> $300-400K | E6: =L32 -> 366000 | H6: =COUNTIF(d_price,"<300000")/COUNT(d_price) -> 0.256 | K6: =COUNTIF(d_price,">=600000")/COUNT(d_price) -> 0.06
B7: =MAX(C30:C36)&" homes ("&TEXT(MAX(C30:C36)/C37,"0%")&")" -> 89 homes (36%) | E7: ="Mean "&TEXT(L35,"$#,##0") -> Mean $3,90,400 | H7: ="entry-level homes" -> entry-level homes | K7: ="90th percentile = "&TEXT(L34,"$#,##0") -> 90th percentile = $5,28,800
B9: THE GRAPH | I9: KEY TAKEAWAYS (auto-generated)
I10: ="Most common band: "&INDEX(B30:B36,MATCH(MAX(C30:C36),C30:C36,0))&" ("&MAX(C30:C36)&" homes, "&TEXT(MAX(C30:C36)/C37,"0%")&" of sales)." -> Most common band: $300-400K (89 homes, 36% of sales).
I13: ="The middle 50% of homes sold between "&TEXT(L31,"$#,##0")&" and "&TEXT(L33,"$#,##0")&" (IQR "&TEXT(L37,"$#,##0")&")." -> The middle 50% of homes sold between $2,97,250 and $4,50,000 (IQR $1,52,750).
I16: ="Mean ("&TEXT(L35,"$#,##0")&") is "&TEXT(L35/L32-1,"0.0%")&IF(L35>L32," above"," below")&" the median ("&TEXT(L32,"$#,##0")&"); skewness "&TEXT(L38,"0.0")&IF(L38>1," = strong right tail from luxury sales."," = fairly balanced.") -> Mean ($3,90,400) is 6.7% above the median ($3,66,000); skewness 9.2 = strong right tail from luxury sales.
I19: ="Entry-level (<$300K) is "&TEXT(COUNTIF(d_price,"<300000")/COUNT(d_price),"0%")&" of sales vs only "&TEXT(COUNTIF(d_price,">=600000")/COUNT(d_price),"0%")&" at $600K+." -> Entry-level (<$300K) is 26% of sales vs only 6% at $600K+.
I22: ="Price per sq ft goes from "&TEXT(F30,"$#,##0")&" in the lowest band to "&TEXT(F36,"$#,##0")&" in the top band." -> Price per sq ft goes from $209 in the lowest band to $416 in the top band.
B28: DATA BEHIND THE GRAPH
B29: Price Band | C29: Sales | D29: % of Sales | E29: Cumulative % | F29: Avg $/sqft | G29: Avg DOM | H29: Avg Sq Ft | J29: Price statistic | L29: Value
B30: =Pivots!A66 -> Under $200K | C30: =Pivots!C66 -> 17 | D30: =Pivots!D66 -> 0.068 | E30: =SUM(D$30:D30) -> 0.068 | F30: =Pivots!E66 -> 208.59442 | G30: =Pivots!F66 -> 69.705882 | H30: =IFERROR(AVERAGEIFS(d_sqft,d_band,B30),"") -> 821.76471 | J30: 10th percentile | L30: =PERCENTILE(d_price,0.1) -> 231800
B31: =Pivots!A67 -> $200-300K | C31: =Pivots!C67 -> 47 | D31: =Pivots!D67 -> 0.188 | E31: =SUM(D$30:D31) -> 0.256 | F31: =Pivots!E67 -> 200.79541 | G31: =Pivots!F67 -> 64.744186 | H31: =IFERROR(AVERAGEIFS(d_sqft,d_band,B31),"") -> 1350.6383 | J31: 25th percentile (Q1) | L31: =QUARTILE(d_price,1) -> 297250
B32: =Pivots!A68 -> $300-400K | C32: =Pivots!C68 -> 89 | D32: =Pivots!D68 -> 0.356 | E32: =SUM(D$30:D32) -> 0.612 | F32: =Pivots!E68 -> 216.53975 | G32: =Pivots!F68 -> 54.747126 | H32: =IFERROR(AVERAGEIFS(d_sqft,d_band,B32),"") -> 1668.0899 | J32: Median | L32: =MEDIAN(d_price) -> 366000
B33: =Pivots!A69 -> $400-500K | C33: =Pivots!C69 -> 57 | D33: =Pivots!D69 -> 0.228 | E33: =SUM(D$30:D33) -> 0.84 | F33: =Pivots!E69 -> 239.24878 | G33: =Pivots!F69 -> 53.836364 | H33: =IFERROR(AVERAGEIFS(d_sqft,d_band,B33),"") -> 1938.0702 | J33: 75th percentile (Q3) | L33: =QUARTILE(d_price,3) -> 450000
B34: =Pivots!A70 -> $500-600K | C34: =Pivots!C70 -> 25 | D34: =Pivots!D70 -> 0.1 | E34: =SUM(D$30:D34) -> 0.94 | F34: =Pivots!E70 -> 248.82454 | G34: =Pivots!F70 -> 54.92 | H34: =IFERROR(AVERAGEIFS(d_sqft,d_band,B34),"") -> 2184 | J34: 90th percentile | L34: =PERCENTILE(d_price,0.9) -> 528800
B35: =Pivots!A71 -> $600-800K | C35: =Pivots!C71 -> 13 | D35: =Pivots!D71 -> 0.052 | E35: =SUM(D$30:D35) -> 0.992 | F35: =Pivots!E71 -> 271.61688 | G35: =Pivots!F71 -> 54.769231 | H35: =IFERROR(AVERAGEIFS(d_sqft,d_band,B35),"") -> 2438.4615 | J35: Mean | L35: =AVERAGE(d_price) -> 390400
B36: =Pivots!A72 -> $800K+ | C36: =Pivots!C72 -> 2 | D36: =Pivots!D72 -> 0.008 | E36: =SUM(D$30:D36) -> 1 | F36: =Pivots!E72 -> 415.86987 | G36: =Pivots!F72 -> 53 | H36: =IFERROR(AVERAGEIFS(d_sqft,d_band,B36),"") -> 4540 | J36: Std deviation | L36: =STDEV(d_price) -> 222755.98
B37: Total | C37: =SUM(C30:C36) -> 250 | D37: =SUM(D30:D36) -> 1 | J37: Interquartile range | L37: =QUARTILE(d_price,3)-QUARTILE(d_price,1) -> 152750
B38: Band limits are editable (blue cells) on the Pivots sheet, section 6. | J38: Skewness | L38: =SKEW(d_price) -> 9.1541078

Sheet D6_Size_vs_Price
B1: 6 ▸ SIZE VS. PRICE — DRILL-DOWN
B2: How living area relates to price: size bands, regression, correlations and a price estimator.
B3: ◂ Back to Dashboard | C3: ◂ Previous graph | E3: Next graph ▸ | G3: Graph 6 of 8 • use the buttons to move between graphs or return to the dashboard
B5: CORRELATION (SQ FT vs PRICE) | E5: EXTRA PRICE PER SQ FT | H5: R² (EXCL. OUTLIERS) | K5: MEDIAN LIVING AREA
B6: =Analysis!B30 -> 0.79506555 | E6: =Analysis!C42 -> 183.53507 | H6: =Analysis!C44 -> 0.5861835 | K6: =MEDIAN(d_sqft) -> 1740
B7: =Analysis!C30&" relationship" -> Strong relationship | E7: ="outliers excluded" -> outliers excluded | H7: ="of price variation explained by size" -> of price variation explained by size | K7: ="sq ft (typical home)" -> sq ft (typical home)
B9: THE GRAPH | I9: KEY TAKEAWAYS (auto-generated)
I10: ="Square footage explains about "&TEXT(Analysis!C44,"0%")&" of price variation; each extra sq ft adds ≈ "&TEXT(Analysis!C42,"$#,##0")&"." -> Square footage explains about 59% of price variation; each extra sq ft adds ≈ $184.
I13: ="Average $/sq ft goes from "&TEXT(G30,"$#,##0")&" (under 1,000 sq ft) to "&TEXT(G34,"$#,##0")&" (2,500+)"&IF(G34>G30,": bigger homes also carry a higher price per sq ft.",": smaller homes carry a higher price per sq ft (typical of condos).") -> Average $/sq ft goes from $245 (under 1,000 sq ft) to $227 (2,500+): smaller homes carry a higher price per sq ft (typical of condos).
I16: ="Lot size (r = "&TEXT(Analysis!B31,"0.00")&") and bedrooms (r = "&TEXT(Analysis!B32,"0.00")&") also track price, but they overlap with size." -> Lot size (r = 0.78) and bedrooms (r = 0.54) also track price, but they overlap with size.
I19: ="Year built shows "&IF(ABS(Analysis!B35)<0.2,"almost no","some")&" relationship with price (r = "&TEXT(Analysis!B35,"0.00")&")." -> Year built shows almost no relationship with price (r = 0.12).
I22: ="Even with sq ft, estimates are off by ≈ "&TEXT(Analysis!C45,"$#,##0")&" on average — location and type matter too." -> Even with sq ft, estimates are off by ≈ $74,997 on average — location and type matter too.
B28: DATA BEHIND THE GRAPH
B29: Size Band | C29: From (sq ft) | D29: To (sq ft) | E29: Sales | F29: Avg Price | G29: Avg $/sqft | H29: Avg Beds | I29: Avg DOM | J29: Δ Price vs prev band
B30: Under 1,000 | C30: 0 | D30: 999 | E30: =COUNTIFS(d_sqft,">="&$C30,d_sqft,"<="&$D30) -> 24 | F30: =IFERROR(AVERAGEIFS(d_price,d_sqft,">="&$C30,d_sqft,"<="&$D30),"") -> 201541.67 | G30: =IFERROR(AVERAGEIFS(d_psf,d_sqft,">="&$C30,d_sqft,"<="&$D30),"") -> 245.00888 | H30: =IFERROR(AVERAGEIFS(d_beds,d_sqft,">="&$C30,d_sqft,"<="&$D30),"") -> 1.0833333 | I30: =IFERROR(AVERAGEIFS(d_dom,d_sqft,">="&$C30,d_sqft,"<="&$D30),"") -> 66.916667 | J30: —
B31: 1,000 - 1,499 | C31: 1000 | D31: 1499 | E31: =COUNTIFS(d_sqft,">="&$C31,d_sqft,"<="&$D31) -> 56 | F31: =IFERROR(AVERAGEIFS(d_price,d_sqft,">="&$C31,d_sqft,"<="&$D31),"") -> 308196.43 | G31: =IFERROR(AVERAGEIFS(d_psf,d_sqft,">="&$C31,d_sqft,"<="&$D31),"") -> 239.87885 | H31: =IFERROR(AVERAGEIFS(d_beds,d_sqft,">="&$C31,d_sqft,"<="&$D31),"") -> 2.0178571 | I31: =IFERROR(AVERAGEIFS(d_dom,d_sqft,">="&$C31,d_sqft,"<="&$D31),"") -> 56.351852 | J31: =IFERROR(F31-F30,"") -> 106654.76
B32: 1,500 - 1,999 | C32: 1500 | D32: 1999 | E32: =COUNTIFS(d_sqft,">="&$C32,d_sqft,"<="&$D32) -> 105 | F32: =IFERROR(AVERAGEIFS(d_price,d_sqft,">="&$C32,d_sqft,"<="&$D32),"") -> 382342.86 | G32: =IFERROR(AVERAGEIFS(d_psf,d_sqft,">="&$C32,d_sqft,"<="&$D32),"") -> 217.45631 | H32: =IFERROR(AVERAGEIFS(d_beds,d_sqft,">="&$C32,d_sqft,"<="&$D32),"") -> 3.1142857 | I32: =IFERROR(AVERAGEIFS(d_dom,d_sqft,">="&$C32,d_sqft,"<="&$D32),"") -> 57.752475 | J32: =IFERROR(F32-F31,"") -> 74146.429
B33: 2,000 - 2,499 | C33: 2000 | D33: 2499 | E33: =COUNTIFS(d_sqft,">="&$C33,d_sqft,"<="&$D33) -> 48 | F33: =IFERROR(AVERAGEIFS(d_price,d_sqft,">="&$C33,d_sqft,"<="&$D33),"") -> 480979.17 | G33: =IFERROR(AVERAGEIFS(d_psf,d_sqft,">="&$C33,d_sqft,"<="&$D33),"") -> 218.26821 | H33: =IFERROR(AVERAGEIFS(d_beds,d_sqft,">="&$C33,d_sqft,"<="&$D33),"") -> 4.0833333 | I33: =IFERROR(AVERAGEIFS(d_dom,d_sqft,">="&$C33,d_sqft,"<="&$D33),"") -> 54.489362 | J33: =IFERROR(F33-F32,"") -> 98636.31
